Workbook
Name data: data1[]
Name Datatable: data1[]
Name NativeTimeline_Deployment_Date: #N/A
Name Rawdata: data1[]
Name Slicer_Mission_Type: #N/A
Name Slicer_Platform: #N/A
Name Slicer_Region: #N/A

Sheet raw_data
A1: System_ID | B1: Platform | C1: System_Type | D1: Manufacturer | E1: Deployment_Date | F1: Region | G1: Mission_Type | H1: Threat_Level | I1: Success_Rate | J1: Response_Time_ms | K1: Uptime_% | L1: Maintenance_Hours_per_Month | M1: Energy_Consumption_kWh | N1: Cost_per_Hour_USD | O1: Annual_Operating_Hours | P1: Annual_Maintenance_Cost_USD | Q1: Energy_Cost_per_kWh_USD | R1: Annual_Budget_Allocation_USD | S1: Replacement_Cost_USD | T1: Deployment_Priority | U1: Annua_ OP _Cost
A2: SYS-001 | B2: Drone | C2: ISR | D2: AeroTech | E2: 45296 | F2: EU | G2: Surveillance | H2: Medium | I2: 0.93 | J2: 180 | K2: 99.1 | L2: 12 | M2: 420 | N2: 1850 | O2: 2200 | P2: 85000 | Q2: 0.18 | R2: 4100000 | S2: 2800000 | T2: 4 | U2: =data1[[#This Row],[Annual_Operating_Hours]]*data1[[#This Row],[Cost_per_Hour_USD]] -> 4070000
A3: SYS-002 | B3: Drone | C3: Combat | D3: SkyForge | E3: 45301 | F3: ME | G3: Strike | H3: High | I3: 0.88 | J3: 230 | K3: 97.5 | L3: 18 | M3: 480 | N3: 2100 | O3: 2400 | P3: 120000 | Q3: 0.18 | R3: 5100000 | S3: 3500000 | T3: 5 | U3: =data1[[#This Row],[Annual_Operating_Hours]]*data1[[#This Row],[Cost_per_Hour_USD]] -> 5040000
A4: SYS-003 | B4: Satellite | C4: ISR | D4: OrbitalSys | E4: 45305 | F4: NA | G4: Tracking | H4: Medium | I4: 0.96 | J4: 95 | K4: 99.8 | L4: 9 | M4: 1500 | N4: 4500 | O4: 8000 | P4: 150000 | Q4: 0.14 | R4: 9100000 | S4: 12000000 | T4: 5 | U4: =data1[[#This Row],[Annual_Operating_Hours]]*data1[[#This Row],[Cost_per_Hour_USD]] -> 36000000
A5: SYS-004 | B5: Radar | C5: Defense | D5: DefenCore | E5: 45309 | F5: APAC | G5: Detection | H5: High | I5: 0.91 | J5: 120 | K5: 98.7 | L5: 15 | M5: 900 | N5: 3200 | O5: 6000 | P5: 130000 | Q5: 0.16 | R5: 7200000 | S5: 9000000 | T5: 5 | U5: =data1[[#This Row],[Annual_Operating_Hours]]*data1[[#This Row],[Cost_per_Hour_USD]] -> 19200000
A6: SYS-005 | B6: UGV | C6: Combat | D6: MechaDyn | E6: 45313 | F6: EU | G6: Patrol | H6: Medium | I6: 0.86 | J6: 260 | K6: 96.9 | L6: 22 | M6: 650 | N6: 1750 | O6: 2000 | P6: 90000 | Q6: 0.17 | R6: 3600000 | S6: 2600000 | T6: 3 | U6: =data1[[#This Row],[Annual_Operating_Hours]]*data1[[#This Row],[Cost_per_Hour_USD]] -> 3500000
A7: SYS-006 | B7: Drone | C7: ISR | D7: AeroTech | E7: 45323 | F7: NA | G7: Surveillance | H7: Low | I7: 0.94 | J7: 170 | K7: 99.3 | L7: 11 | M7: 410 | N7: 1820 | O7: 2300 | P7: 82000 | Q7: 0.18 | R7: 4200000 | S7: 2800000 | T7: 4 | U7: =data1[[#This Row],[Annual_Operating_Hours]]*data1[[#This Row],[Cost_per_Hour_USD]] -> 4186000
A8: SYS-007 | B8: Satellite | C8: Navigation | D8: OrbitalSys | E8: 45327 | F8: APAC | G8: Guidance | H8: Low | I8: 0.97 | J8: 85 | K8: 99.9 | L8: 7 | M8: 1600 | N8: 4800 | O8: 8200 | P8: 160000 | Q8: 0.14 | R8: 9400000 | S8: 12500000 | T8: 5 | U8: =data1[[#This Row],[Annual_Operating_Hours]]*data1[[#This Row],[Cost_per_Hour_USD]] -> 39360000
A9: SYS-008 | B9: Radar | C9: Defense | D9: DefenCore | E9: 45334 | F9: ME | G9: Detection | H9: High | I9: 0.89 | J9: 145 | K9: 97.8 | L9: 19 | M9: 940 | N9: 3300 | O9: 6200 | P9: 140000 | Q9: 0.16 | R9: 7500000 | S9: 9200000 | T9: 5 | U9: =data1[[#This Row],[Annual_Operating_Hours]]*data1[[#This Row],[Cost_per_Hour_USD]] -> 20460000
A10: SYS-009 | B10: Drone | C10: Combat | D10: SkyForge | E10: 45342 | F10: EU | G10: Strike | H10: High | I10: 0.85 | J10: 250 | K10: 96.2 | L10: 23 | M10: 510 | N10: 2150 | O10: 2400 | P10: 125000 | Q10: 0.18 | R10: 5200000 | S10: 3600000 | T10: 5 | U10: =data1[[#This Row],[Annual_Operating_Hours]]*data1[[#This Row],[Cost_per_Hour_USD]] -> 5160000
A11: SYS-010 | B11: UGV | C11: Logistics | D11: MechaDyn | E11: 45352 | F11: NA | G11: Supply | H11: Low | I11: 0.92 | J11: 200 | K11: 98.9 | L11: 14 | M11: 600 | N11: 1700 | O11: 2100 | P11: 88000 | Q11: 0.17 | R11: 3700000 | S11: 2500000 | T11: 3 | U11: =data1[[#This Row],[Annual_Operating_Hours]]*data1[[#This Row],[Cost_per_Hour_USD]] -> 3570000
A12: SYS-011 | B12: Satellite | C12: ISR | D12: OrbitalSys | E12: 45359 | F12: EU | G12: Tracking | H12: Medium | I12: 0.95 | J12: 100 | K12: 99.5 | L12: 10 | M12: 1550 | N12: 4600 | O12: 8100 | P12: 150000 | Q12: 0.14 | R12: 9000000 | S12: 12000000 | T12: 5 | U12: =data1[[#This Row],[Annual_Operating_Hours]]*data1[[#This Row],[Cost_per_Hour_USD]] -> 37260000
A13: SYS-012 | B13: Radar | C13: Defense | D13: DefenCore | E13: 45366 | F13: APAC | G13: Detection | H13: Medium | I13: 0.9 | J13: 130 | K13: 98.1 | L13: 16 | M13: 910 | N13: 3250 | O13: 6100 | P13: 132000 | Q13: 0.16 | R13: 7300000 | S13: 9100000 | T13: 4 | U13: =data1[[#This Row],[Annual_Operating_Hours]]*data1[[#This Row],[Cost_per_Hour_USD]] -> 19825000
... A101: SYS-100 | B101: Radar | C101: Defense | D101: DefenCore | E101: 46050 | F101: NA | G101: Detection | H101: High | I101: 0.9 | J101: 140 | K101: 97.8 | L101: 17 | M101: 940 | N101: 3320 | O101: 6300 | P101: 138000 | Q101: 0.16 | R101: 7500000 | S101: 9250000 | T101: 4 | U101: =data1[[#This Row],[Annual_Operating_Hours]]*data1[[#This Row],[Cost_per_Hour_USD]] -> 20916000

Sheet program_cost_model
A1: System_ID | B1: Annual_Operating_Hours | C1: Annual_Maintenance_Cost_USD | D1: Energy_Cost_per_kWh_USD | E1: Annual_Budget_Allocation_USD | F1: Replacement_Cost_USD | G1: Deployment_Priority
A2: SYS-001 | B2: 2200 | C2: 85000 | D2: 0.18 | E2: 4100000 | F2: 2800000 | G2: 4
A3: SYS-002 | B3: 2400 | C3: 120000 | D3: 0.18 | E3: 5100000 | F3: 3500000 | G3: 5
A4: SYS-003 | B4: 8000 | C4: 150000 | D4: 0.14 | E4: 9100000 | F4: 12000000 | G4: 5
A5: SYS-004 | B5: 6000 | C5: 130000 | D5: 0.16 | E5: 7200000 | F5: 9000000 | G5: 5
A6: SYS-005 | B6: 2000 | C6: 90000 | D6: 0.17 | E6: 3600000 | F6: 2600000 | G6: 3
A7: SYS-006 | B7: 2300 | C7: 82000 | D7: 0.18 | E7: 4200000 | F7: 2800000 | G7: 4
A8: SYS-007 | B8: 8200 | C8: 160000 | D8: 0.14 | E8: 9400000 | F8: 12500000 | G8: 5
A9: SYS-008 | B9: 6200 | C9: 140000 | D9: 0.16 | E9: 7500000 | F9: 9200000 | G9: 5
A10: SYS-009 | B10: 2400 | C10: 125000 | D10: 0.18 | E10: 5200000 | F10: 3600000 | G10: 5
A11: SYS-010 | B11: 2100 | C11: 88000 | D11: 0.17 | E11: 3700000 | F11: 2500000 | G11: 3
A12: SYS-011 | B12: 8100 | C12: 150000 | D12: 0.14 | E12: 9000000 | F12: 12000000 | G12: 5
A13: SYS-012 | B13: 6100 | C13: 132000 | D13: 0.16 | E13: 7300000 | F13: 9100000 | G13: 4
... A101: SYS-100 | B101: 6300 | C101: 138000 | D101: 0.16 | E101: 7500000 | F101: 9250000 | G101: 4

Sheet Intro
H4: Project 2 -Scenario Analysis of Defense Fleet Operations and Budget
I7: Project summary | J7: This workbook analyzes the performance and operating costs of a mixed fleet of defense systems across multiple regions, platforms, and mission types. It combines raw operational data with a cost model and scenario multipliers to simulate how budgets, threats, maintenance, and energy conditions affect total annual cost and readiness. The goal is to help decision‑makers understand cost drivers, identify high‑impact levers, and prioritize investments under different strategic scenarios
I8: Objectives | J8: Provide a clear snapshot of fleet performance by platform, mission type, and region.
J9: Quantify total annual cost, including operations, maintenance, and energy, against the available budget.
J10: Simulate key scenarios (e.g., War Surge, Energy Crisis, Budget Cuts) using transparent multipliers.
J11: Highlight the most effective levers (cost, maintenance, energy, readiness) to close budget gaps.
J12: Support recommendations for which platforms or regions to prioritize under constrained resources

Sheet Dashboard
I3: Integrated Dashboard

Sheet scenario_multipliers
A1: Scenario | B1: Region | C1: Threat_Multiplier | D1: Cost_Multiplier | E1: Maintenance_Multiplier | F1: Energy_Multiplier | G1: Readiness_Multiplier
A2: Baseline | B2: All | C2: 1 | D2: 1 | E2: 1 | F2: 1 | G2: 1
A3: Budget_Cut_20 | B3: All | C3: 1 | D3: 0.8 | E3: 1 | F3: 1 | G3: 0.95
A4: High_Threat_ME | B4: ME | C4: 1.3 | D4: 1.15 | E4: 1.25 | F4: 1.1 | G4: 0.9
A5: Energy_Crisis | B5: Global | C5: All | D5: 1 | E5: 1 | F5: 1.4 | G5: 0.85
A6: War_Surge | B6: ME | C6: 1.5 | D6: 1.3 | E6: 1.4 | F6: 1.2 | G6: 0.8
A7: Pacific_Escalation | B7: APAC | C7: 1.4 | D7: 1.2 | E7: 1.3 | F7: 1.15 | G7: 0.88
A8: Maintenance_Shock | B8: Global | C8: All | D8: 1 | E8: 1.5 | F8: 1 | G8: 0.9
D13: Adjusted
A14: Scenarios | B14: Adjusted_Total_Cost | C14: Threat_Multiplier | D14: Cost_Multiplier | E14: Maintenance_Multiplier | F14: Energy_Multiplier | G14: Readiness_Multiplier
A15: {=Table3[Scenario]} -> Baseline | B15: =(Calcul!$G$102)* (scenario_multipliers!D2)*(scenario_multipliers!E2)*(scenario_multipliers!F2) -> 1.7983995e+09 | C15: 1 | D15: 1 | E15: 1 | F15: 1 | G15: 1
A16: Budget_Cut_20 | B16: =(Calcul!$G$102)*(D16)*(E16)*(F16) -> 1.4387196e+09 | C16: 1 | D16: 0.8 | E16: 1 | F16: 1 | G16: 0.95
A17: High_Threat_ME | B17: =(Calcul!$G$102)*(D17)*(E17)*(F17) -> 2.8437192e+09 | C17: 1.3 | D17: 1.15 | E17: 1.25 | F17: 1.1 | G17: 0.9
A18: Energy_Crisis | B18: =(Calcul!$G$102)*(D18)*(E18)*(F18) -> 2.5177593e+09 | C18: All | D18: 1 | E18: 1 | F18: 1.4 | G18: 0.85
A19: War_Surge | B19: =(Calcul!$G$102)*(D19)*(E19)*(F19) -> 3.9277045e+09 | C19: 1.5 | D19: 1.3 | E19: 1.4 | F19: 1.2 | G19: 0.8
A20: Pacific_Escalation | B20: =(Calcul!$G$102)*(D20)*(E20)*(F20) -> 3.2263287e+09 | C20: 1.4 | D20: 1.2 | E20: 1.3 | F20: 1.15 | G20: 0.88
A21: Maintenance_Shock | B21: =(Calcul!$G$102)*(D21)*(E21)*(F21) -> 2.6975992e+09 | C21: All | D21: 1 | E21: 1.5 | F21: 1 | G21: 0.9
A28: War_Surge | B28: =(Calcul!$G$102)*(D28)*(E28)*(F28) -> 3.9277045e+09 | C28: Goal Seeker | D28: 1.3 | E28: 1.4 | F28: 1.2 | H28: =(Calcul!$G$102)*J28*K28*L28 -> 2.5177593e+09 | I28: OG | J28: 1 | K28: 1 | L28: 1.4
B29: =(Calcul!$G$102)*(D29)*(E29)*(F29) -> 2.2e+09 | C29: Cost | D29: 0.72816069 | E29: 1.4 | F29: 1.2 | H29: =(Calcul!$G$102)*(J29)*(K29)*(L29) -> 2e+09 | I29: Cost | J29: 0.79435712 | K29: 1 | L29: 1.4
B30: =(Calcul!$G$102)*(D30)*(E30)*(F30) -> 2.2e+09 | C30: Manitenance | D30: 1.3 | E30: 0.78417305 | F30: 1.2 | H30: =(Calcul!$G$102)*(J30)*(K30)*(L30) -> 2e+09 | I30: Manitenance | J30: 1 | K30: 0.79435712 | L30: 1.4
B31: =(Calcul!$G$102)*(D31)*(E31)*(F31) -> 2200000000 | C31: Energy | D31: 1.3 | E31: 1.4 | F31: 0.67214833 | H31: =(Calcul!$G$102)*(J31)*(K31)*(L31) -> 2e+09 | I31: Energy | J31: 1 | K31: 1 | L31: 1.1121
J32: Baseline | K32: =B15 -> 1.7983995e+09
J33: Cost | K33: 1.3
J34: Manitenance | K34: 1.4
J35: Energy | K35: 1.2
J36: Total Cost | K36: =K32*K33*K34*K35 -> 3.9277045e+09
C39: Cost | D39: Energy
C40: =K36 -> 3.9277045e+09 | D40: 0 | E40: 0.2 | F40: 0.4 | G40: 0.6 | H40: 0.8 | I40: 1 | J40: 1.2
C41: 0 | D41: 0 | E41: 0 | F41: 0 | G41: 0 | H41: 0 | I41: 0 | J41: 0
C42: 0.1 | D42: 0 | E42: 50355185 | F42: 1.0071037e+08 | G42: 1.5106556e+08 | H42: 2.0142074e+08 | I42: 2.5177593e+08 | J42: 3.0213111e+08
C43: 0.2 | D43: 0 | E43: 1.0071037e+08 | F43: 2.0142074e+08 | G43: 3.0213111e+08 | H43: 4.0284148e+08 | I43: 5.0355185e+08 | J43: 6.0426223e+08
C44: 0.3 | D44: 0 | E44: 1.5106556e+08 | F44: 3.0213111e+08 | G44: 4.5319667e+08 | H44: 6.0426223e+08 | I44: 7.5532778e+08 | J44: 9.0639334e+08
C45: 0.4 | D45: 0 | E45: 2.0142074e+08 | F45: 4.0284148e+08 | G45: 6.0426223e+08 | H45: 8.0568297e+08 | I45: 1.0071037e+09 | J45: 1.2085245e+09
C46: 0.5 | D46: 0 | E46: 2.5177593e+08 | F46: 5.0355185e+08 | G46: 7.5532778e+08 | H46: 1.0071037e+09 | I46: 1.2588796e+09 | J46: 1.5106556e+09
C47: 0.6 | D47: 0 | E47: 3.0213111e+08 | F47: 6.0426223e+08 | G47: 9.0639334e+08 | H47: 1.2085245e+09 | I47: 1.5106556e+09 | J47: 1.8127867e+09
C48: 0.7 | D48: 0 | E48: 3.524863e+08 | F48: 7.049726e+08 | G48: 1.0574589e+09 | H48: 1.4099452e+09 | I48: 1.7624315e+09 | J48: 2.1149178e+09
C49: 0.8 | D49: 0 | E49: 4.0284148e+08 | F49: 8.0568297e+08 | G49: 1.2085245e+09 | H49: 1.6113659e+09 | I49: 2.0142074e+09 | J49: 2.4170489e+09
C50: 0.9 | D50: 0 | E50: 4.5319667e+08 | F50: 9.0639334e+08 | G50: 1.35959e+09 | H50: 1.8127867e+09 | I50: 2.2659833e+09 | J50: 2.71918e+09
C51: 1 | D51: 0 | E51: 5.0355185e+08 | F51: 1.0071037e+09 | G51: 1.5106556e+09 | H51: 2.0142074e+09 | I51: 2.5177593e+09 | J51: 3.0213111e+09
C52: 1.1 | D52: 0 | E52: 5.5390704e+08 | F52: 1.1078141e+09 | G52: 1.6617211e+09 | H52: 2.2156282e+09 | I52: 2.7695352e+09 | J52: 3.3234422e+09
...

Sheet validation
A1: Filter_Type | B1: Selection | C1: Available_Values | D1: Platform | E1: Region | F1: Mission_Type | G1: Manufacturer | H1: Threat_Level | K1: Threat = 1 → no escalation
A2: Platform | B2: (dropdown) | D2: {=_xlfn.UNIQUE(data1[Platform])} -> Drone | E2: {=_xlfn.UNIQUE(data1[Region])} -> EU | F2: {=_xlfn.UNIQUE(data1[Mission_Type])} -> Surveillance | G2: {=_xlfn.UNIQUE(data1[Manufacturer])} -> AeroTech | H2: {=_xlfn.UNIQUE(data1[Threat_Level])} -> Medium
A3: Region | B3: (dropdown) | D3: Satellite | E3: ME | F3: Strike | G3: SkyForge | H3: High | K3: Cost = 1 → no budget change
A4: Mission_Type | B4: (dropdown) | D4: Radar | E4: NA | F4: Tracking | G4: OrbitalSys | H4: Low
A5: Manufacturer | B5: (dropdown) | D5: UGV | E5: APAC | F5: Detection | G5: DefenCore | K5: Maintenance = 1 → no stress
A6: Threat_Level | B6: (dropdown) | F6: Patrol | G6: MechaDyn
F7: Guidance | K7: Energy = 1 → stable energy market
F8: Supply
K9: Readiness = 1 → normal readiness
K11: That’s why all multipliers = 1.
A13: Threat_Level | B13: Threat_Score | K13: And suddenly:
A14: Medium | B14: 1
A15: High | B15: 1.3 | K15: You can simulate war
K17: You can simulate energy collapse
K19: You can simulate budget austerity
K21: You can simulate regional escalation

Sheet Scenario Analysis
A1: Baseline Scenario
A3: Scenarios | B3: Adjusted_Total_Cost
A4: {=Table3[Scenario]} -> Baseline | B4: =(Calcul!$G$102)*(scenario_multipliers!D15)*(scenario_multipliers!E15)*scenario_multipliers!F15 -> 1.7983995e+09
A5: Budget_Cut_20 | B5: =(Calcul!$G$102)*(scenario_multipliers!D16)*(scenario_multipliers!E16)*scenario_multipliers!F16 -> 1.4387196e+09
A6: High_Threat_ME | B6: =(Calcul!$G$102)*(scenario_multipliers!D17)*(scenario_multipliers!E17)*scenario_multipliers!F17 -> 2.8437192e+09
A7: Energy_Crisis | B7: =(Calcul!$G$102)*(scenario_multipliers!D18)*(scenario_multipliers!E18)*scenario_multipliers!F18 -> 2.5177593e+09
A8: War_Surge | B8: =(Calcul!$G$102)*(scenario_multipliers!D19)*(scenario_multipliers!E19)*scenario_multipliers!F19 -> 3.9277045e+09
A9: Pacific_Escalation | B9: =(Calcul!$G$102)*(scenario_multipliers!D20)*(scenario_multipliers!E20)*scenario_multipliers!F20 -> 3.2263287e+09
A10: Maintenance_Shock | B10: =(Calcul!$G$102)*(scenario_multipliers!D21)*(scenario_multipliers!E21)*scenario_multipliers!F21 -> 2.6975992e+09
A13: War Surge | F13: Energy Crisis
A15: Target KPI | B15: Value | F15: Target KPI | G15: Value
A16: Budget Ceiling | B16: $2.2B | F16: Budget Ceiling | G16: 2000000000
A17: Current War Surge | B17: $3.93B | F17: Current War Surge | G17: =B7 -> 2.5177593e+09
A18: Gap | B18: $1.73B | F18: Gap | G18: =G17-G16 -> 5.1775927e+08
A21: Lever | B21: Old | C21: New | D21: Required Change | F21: Lever | G21: Old | H21: New | I21: Required Change
A22: Cost Multiplier | B22: =scenario_multipliers!D19 -> 1.3 | C22: =scenario_multipliers!D29 -> 0.72816069 | D22: =C22-B22 -> -0.57183931 | F22: Cost Multiplier | G22: =scenario_multipliers!J28 -> 1 | H22: =scenario_multipliers!J29 -> 0.79435712 | I22: =H22-G22 -> -0.20564288
A23: Manitenance Multiplier | B23: =scenario_multipliers!E28 -> 1.4 | C23: =scenario_multipliers!E30 -> 0.78417305 | D23: =C23-B23 -> -0.61582695 | F23: Manitenance Multiplier | G23: =scenario_multipliers!K28 -> 1 | H23: =scenario_multipliers!K30 -> 0.79435712 | I23: =H23-G23 -> -0.20564288
A24: Energy Multiplier | B24: =scenario_multipliers!F28 -> 1.2 | C24: =scenario_multipliers!F31 -> 0.67214833 | D24: =C24-B24 -> -0.52785167 | F24: Energy Multiplier | G24: =scenario_multipliers!L28 -> 1.4 | H24: =scenario_multipliers!L31 -> 1.1121 | I24: =H24-G24 -> -0.28790003
A26: Comparison table
A27: Lever | B27: Required Change | C27: Feasibility | D27: Strategic Impact
A28: Cost Multiplier | B28: -0.57183931 | C28: Medium | D28: High
A29: Manitenance Multiplier | B29: -0.61582695 | C29: High | D29: Medium
A30: Energy Multiplier | B30: -0.52785167 | C30: Low | D30: Medium
A33: Data Table
A35: Baseline | B35: =B4 -> 1.7983995e+09
A36: Cost | B36: 1.3
A37: Manitenance | B37: 1.4
A38: Energy | B38: 1.2
A39: Total Cost | B39: =B35*B36*B37*B38 -> 3.9277045e+09
A42: Cost | B42: Energy
A43: =B39 -> 3.9277045e+09 | B43: 0 | C43: 0.2 | D43: 0.4 | E43: 0.6 | F43: 0.8 | G43: 1 | H43: 1.2
A44: 0 | B44: 0 | C44: 0 | D44: 0 | E44: 0 | F44: 0 | G44: 0 | H44: 0
A45: 0.1 | B45: 0 | C45: 50355185 | D45: 1.0071037e+08 | E45: 1.5106556e+08 | F45: 2.0142074e+08 | G45: 2.5177593e+08 | H45: 3.0213111e+08
A46: 0.2 | B46: 0 | C46: 1.0071037e+08 | D46: 2.0142074e+08 | E46: 3.0213111e+08 | F46: 4.0284148e+08 | G46: 5.0355185e+08 | H46: 6.0426223e+08
A47: 0.3 | B47: 0 | C47: 1.5106556e+08 | D47: 3.0213111e+08 | E47: 4.5319667e+08 | F47: 6.0426223e+08 | G47: 7.5532778e+08 | H47: 9.0639334e+08
A48: 0.4 | B48: 0 | C48: 2.0142074e+08 | D48: 4.0284148e+08 | E48: 6.0426223e+08 | F48: 8.0568297e+08 | G48: 1.0071037e+09 | H48: 1.2085245e+09
A49: 0.5 | B49: 0 | C49: 2.5177593e+08 | D49: 5.0355185e+08 | E49: 7.5532778e+08 | F49: 1.0071037e+09 | G49: 1.2588796e+09 | H49: 1.5106556e+09
A50: 0.6 | B50: 0 | C50: 3.0213111e+08 | D50: 6.0426223e+08 | E50: 9.0639334e+08 | F50: 1.2085245e+09 | G50: 1.5106556e+09 | H50: 1.8127867e+09
A51: 0.7 | B51: 0 | C51: 3.524863e+08 | D51: 7.049726e+08 | E51: 1.0574589e+09 | F51: 1.4099452e+09 | G51: 1.7624315e+09 | H51: 2.1149178e+09
A52: 0.8 | B52: 0 | C52: 4.0284148e+08 | D52: 8.0568297e+08 | E52: 1.2085245e+09 | F52: 1.6113659e+09 | G52: 2.0142074e+09 | H52: 2.4170489e+09
...

Sheet Calcul
A1: Platform | B1: Cost Per hour | C1: Annual Hours | D1: Total Cost Annual | E1: Annual Energy Consumption Cost | F1: Maintenance cost | G1: Total Annual Cost | H1: Readiness Score | I1: Risk Index
A2: {=data1[Platform]} -> Drone | B2: {=data1[Cost_per_Hour_USD]} -> 1850 | C2: {=data1[Annual_Operating_Hours]} -> 2200 | D2: =B2*C2 -> 4070000 | E2: {=(data1[Energy_Consumption_kWh]) * (data1[Energy_Cost_per_kWh_USD]) *(data1[Annual_Operating_Hours])} -> 166320 | F2: {=data1[Annual_Maintenance_Cost_USD]} -> 85000 | G2: =SUM($D2,$E2,$F2) -> 4321320 | H2: {=(data1[Uptime_%]) * (data1[Success_Rate])} -> 92.163 | I2: =IFERROR(_xlfn.XLOOKUP(data1[[#This Row],[Threat_Level]],validation!$A$14:$A$15,validation!$B$14:$B$15),"")
A3: Drone | B3: 2100 | C3: 2400 | D3: =B3*C3 -> 5040000 | E3: 207360 | F3: 120000 | G3: =SUM($D3,$E3,$F3) -> 5367360 | H3: 85.8 | I3: =IFERROR(_xlfn.XLOOKUP(data1[[#This Row],[Threat_Level]],validation!$A$14:$A$15,validation!$B$14:$B$15),"") -> 1.3
A4: Satellite | B4: 4500 | C4: 8000 | D4: =B4*C4 -> 36000000 | E4: 1680000 | F4: 150000 | G4: =SUM($D4,$E4,$F4) -> 37830000 | H4: 95.808 | I4: =IFERROR(_xlfn.XLOOKUP(data1[[#This Row],[Threat_Level]],validation!$A$14:$A$15,validation!$B$14:$B$15),"")
A5: Radar | B5: 3200 | C5: 6000 | D5: =B5*C5 -> 19200000 | E5: 864000 | F5: 130000 | G5: =SUM($D5,$E5,$F5) -> 20194000 | H5: 89.817 | I5: =IFERROR(_xlfn.XLOOKUP(data1[[#This Row],[Threat_Level]],validation!$A$14:$A$15,validation!$B$14:$B$15),"") -> 1.3
A6: UGV | B6: 1750 | C6: 2000 | D6: =B6*C6 -> 3500000 | E6: 221000 | F6: 90000 | G6: =SUM($D6,$E6,$F6) -> 3811000 | H6: 83.334 | I6: =IFERROR(_xlfn.XLOOKUP(data1[[#This Row],[Threat_Level]],validation!$A$14:$A$15,validation!$B$14:$B$15),"")
A7: Drone | B7: 1820 | C7: 2300 | D7: =B7*C7 -> 4186000 | E7: 169740 | F7: 82000 | G7: =SUM($D7,$E7,$F7) -> 4437740 | H7: 93.342 | I7: =IFERROR(_xlfn.XLOOKUP(data1[[#This Row],[Threat_Level]],validation!$A$14:$A$15,validation!$B$14:$B$15),"")
A8: Satellite | B8: 4800 | C8: 8200 | D8: =B8*C8 -> 39360000 | E8: 1836800 | F8: 160000 | G8: =SUM($D8,$E8,$F8) -> 41356800 | H8: 96.903 | I8: =IFERROR(_xlfn.XLOOKUP(data1[[#This Row],[Threat_Level]],validation!$A$14:$A$15,validation!$B$14:$B$15),"")
A9: Radar | B9: 3300 | C9: 6200 | D9: =B9*C9 -> 20460000 | E9: 932480 | F9: 140000 | G9: =SUM($D9,$E9,$F9) -> 21532480 | H9: 87.042 | I9: =IFERROR(_xlfn.XLOOKUP(data1[[#This Row],[Threat_Level]],validation!$A$14:$A$15,validation!$B$14:$B$15),"") -> 1.3
A10: Drone | B10: 2150 | C10: 2400 | D10: =B10*C10 -> 5160000 | E10: 220320 | F10: 125000 | G10: =SUM($D10,$E10,$F10) -> 5505320 | H10: 81.77 | I10: =IFERROR(_xlfn.XLOOKUP(data1[[#This Row],[Threat_Level]],validation!$A$14:$A$15,validation!$B$14:$B$15),"") -> 1.3
A11: UGV | B11: 1700 | C11: 2100 | D11: =B11*C11 -> 3570000 | E11: 214200 | F11: 88000 | G11: =SUM($D11,$E11,$F11) -> 3872200 | H11: 90.988 | I11: =IFERROR(_xlfn.XLOOKUP(data1[[#This Row],[Threat_Level]],validation!$A$14:$A$15,validation!$B$14:$B$15),"")
A12: Satellite | B12: 4600 | C12: 8100 | D12: =B12*C12 -> 37260000 | E12: 1757700 | F12: 150000 | G12: =SUM($D12,$E12,$F12) -> 39167700 | H12: 94.525 | I12: =IFERROR(_xlfn.XLOOKUP(data1[[#This Row],[Threat_Level]],validation!$A$14:$A$15,validation!$B$14:$B$15),"")
A13: Radar | B13: 3250 | C13: 6100 | D13: =B13*C13 -> 19825000 | E13: 888160 | F13: 132000 | G13: =SUM($D13,$E13,$F13) -> 20845160 | H13: 88.29 | I13: =IFERROR(_xlfn.XLOOKUP(data1[[#This Row],[Threat_Level]],validation!$A$14:$A$15,validation!$B$14:$B$15),"")
A14: Drone | B14: 1900 | C14: 2300 | D14: =B14*C14 -> 4370000 | E14: 178020 | F14: 90000 | G14: =SUM($D14,$E14,$F14) -> 4638020 | H14: 89.635 | I14: =IFERROR(_xlfn.XLOOKUP(data1[[#This Row],[Threat_Level]],validation!$A$14:$A$15,validation!$B$14:$B$15),"") -> 1.3
... A101: Radar | B101: 3320 | C101: 6300 | D101: =B101*C101 -> 20916000 | E101: 947520 | F101: 138000 | G101: =SUM($D101,$E101,$F101) -> 22001520 | H101: 88.02 | I101: =IFERROR(_xlfn.XLOOKUP(data1[[#This Row],[Threat_Level]],validation!$A$14:$A$15,validation!$B$14:$B$15),"") -> 1.3
A102: Total | G102: =SUM(G2:G101) -> 1.7983995e+09 | I102: =IFERROR(_xlfn.XLOOKUP(data1[[#This Row],[Threat_Level]],validation!$A$14:$A$15,validation!$B$14:$B$15),"")
I103: =IFERROR(_xlfn.XLOOKUP(data1[[#This Row],[Threat_Level]],validation!$A$14:$A$15,validation!$B$14:$B$15),"")
I104: =IFERROR(_xlfn.XLOOKUP(data1[[#This Row],[Threat_Level]],validation!$A$14:$A$15,validation!$B$14:$B$15),"")
I105: =IFERROR(_xlfn.XLOOKUP(data1[[#This Row],[Threat_Level]],validation!$A$14:$A$15,validation!$B$14:$B$15),"")
I106: =IFERROR(_xlfn.XLOOKUP(data1[[#This Row],[Threat_Level]],validation!$A$14:$A$15,validation!$B$14:$B$15),"")
I107: =IFERROR(_xlfn.XLOOKUP(data1[[#This Row],[Threat_Level]],validation!$A$14:$A$15,validation!$B$14:$B$15),"")
I108: =IFERROR(_xlfn.XLOOKUP(data1[[#This Row],[Threat_Level]],validation!$A$14:$A$15,validation!$B$14:$B$15),"")
I109: =IFERROR(_xlfn.XLOOKUP(data1[[#This Row],[Threat_Level]],validation!$A$14:$A$15,validation!$B$14:$B$15),"")
I110: =IFERROR(_xlfn.XLOOKUP(data1[[#This Row],[Threat_Level]],validation!$A$14:$A$15,validation!$B$14:$B$15),"")
I111: =IFERROR(_xlfn.XLOOKUP(data1[[#This Row],[Threat_Level]],validation!$A$14:$A$15,validation!$B$14:$B$15),"")
I112: =IFERROR(_xlfn.XLOOKUP(data1[[#This Row],[Threat_Level]],validation!$A$14:$A$15,validation!$B$14:$B$15),"")
I113: =IFERROR(_xlfn.XLOOKUP(data1[[#This Row],[Threat_Level]],validation!$A$14:$A$15,validation!$B$14:$B$15),"")
I114: =IFERROR(_xlfn.XLOOKUP(data1[[#This Row],[Threat_Level]],validation!$A$14:$A$15,validation!$B$14:$B$15),"")
... I200: =IFERROR(_xlfn.XLOOKUP(data1[[#This Row],[Threat_Level]],validation!$A$14:$A$15,validation!$B$14:$B$15),"")

Sheet pivots
A1: Average of Success_Rate | B1: Column Labels | I1: Count of Platform | J1: Column Labels | S1: Row Labels | T1: Average of Response_Time_ms
A2: Row Labels | B2: Drone | C2: Radar | D2: Satellite | E2: UGV | F2: Grand Total | I2: Row Labels | J2: High | K2: Low | L2: Medium | M2: Grand Total | S2: Detection | T2: 135.66667
A3: APAC | B3: 0.89666667 | C3: 0.9 | D3: 0.975 | F3: 0.91083333 | I3: Drone | J3: 9 | K3: 3 | L3: 4 | M3: 16 | S3: Guidance | T3: 84.714286
A4: EU | B4: 0.895 | C4: 0.908 | D4: 0.955 | E4: 0.86666667 | F4: 0.90875 | I4: Radar | J4: 8 | L4: 7 | M4: 15 | S4: Patrol | T4: 259.28571
A5: ME | B5: 0.895 | C5: 0.89 | D5: 0.96 | E5: 0.845 | F5: 0.90538462 | I5: Satellite | K5: 7 | L5: 8 | M5: 15 | S5: Strike | T5: 245
A6: NA | B6: 0.905 | C6: 0.92 | D6: 0.968 | E6: 0.86 | F6: 0.925 | I6: UGV | J6: 3 | L6: 4 | M6: 7 | S6: Surveillance | T6: 177.5
A7: Grand Total | B7: 0.898125 | C7: 0.90066667 | D7: 0.96333333 | E7: 0.85857143 | F7: 0.91207547 | I7: Grand Total | J7: 20 | K7: 10 | L7: 23 | M7: 53 | S7: Tracking | T7: 96.625
S8: Grand Total | T8: 162.18868
A11: Row Labels | B11: Average of Annual_Maintenance_Cost_USD
A12: Drone | B12: 107250
A13: Radar | B13: 137333.33
A14: Satellite | B14: 158666.67 | P14: Row Labels | Q14: Sum of Energy_Consumption_kWh
A15: UGV | B15: 107285.71 | I15: Row Labels | J15: Count of System_ID | P15: Drone | Q15: 7575
A16: Grand Total | B16: 130320.75 | I16: APAC | J16: 12 | P16: Radar | Q16: 13950
I17: EU | J17: 16 | P17: Satellite | Q17: 23810
I18: ME | J18: 13 | P18: UGV | Q18: 4750
A19: Row Labels | B19: Average of Annual_Maintenance_Cost_USD | I19: NA | J19: 12 | P19: Grand Total | Q19: 50085
A20: Drone | B20: 107250 | I20: Grand Total | J20: 53
A21: Radar | B21: 137333.33
A22: Satellite | B22: 158666.67
A23: UGV | B23: 107285.71
A24: Grand Total | B24: 130320.75
F26: Count of Mission_Type | G26: Column Labels
F27: Row Labels | G27: Drone | H27: Radar | I27: Satellite | J27: UGV | K27: Grand Total
F28: 2024 | G28: 13 | H28: 12 | I28: 12 | J28: 6 | K28: 43
F29: Qtr1 | G29: 5 | H29: 3 | I29: 3 | J29: 1 | K29: 12
F30: Qtr2 | G30: 2 | H30: 3 | I30: 3 | J30: 2 | K30: 10
F31: Qtr3 | G31: 3 | H31: 3 | I31: 3 | J31: 1 | K31: 10
F32: Qtr4 | G32: 3 | H32: 3 | I32: 3 | J32: 2 | K32: 11
F33: 2025 | G33: 3 | H33: 3 | I33: 3 | J33: 1 | K33: 10
F34: Qtr1 | G34: 3 | H34: 3 | I34: 3 | J34: 1 | K34: 10
F35: Grand Total | G35: 16 | H35: 15 | I35: 15 | J35: 7 | K35: 53
A40: Row Labels | B40: Sum of Annual_Budget_Allocation_USD
A41: Drone | B41: 75550000
A42: 2024 | B42: 60950000
A43: 2025 | B43: 14600000
A44: Radar | B44: 111500000
A45: 2024 | B45: 89150000
A46: 2025 | B46: 22350000
A47: Satellite | B47: 139700000
...
